[2024-03-07 10:54:07,398] torch.distributed.run: [WARNING] master_addr is only used for static rdzv_backend and when rdzv_endpoint is not specified.
[2024-03-07 10:54:07,398] torch.distributed.run: [WARNING] master_addr is only used for static rdzv_backend and when rdzv_endpoint is not specified.
[2024-03-07 10:54:07,398] torch.distributed.run: [WARNING] master_addr is only used for static rdzv_backend and when rdzv_endpoint is not specified.
[2024-03-07 10:54:07,398] torch.distributed.run: [WARNING] master_addr is only used for static rdzv_backend and when rdzv_endpoint is not specified.
[2024-03-07 10:54:07,398] torch.distributed.run: [WARNING] master_addr is only used for static rdzv_backend and when rdzv_endpoint is not specified.
[2024-03-07 10:54:07,398] torch.distributed.run: [WARNING] master_addr is only used for static rdzv_backend and when rdzv_endpoint is not specified.
Traceback (most recent call last):
  File "train.py", line 1, in <module>
    from datasets import load_from_disk, load_dataset
ModuleNotFoundError: No module named 'datasets'
Traceback (most recent call last):
  File "train.py", line 1, in <module>
    from datasets import load_from_disk, load_dataset
ModuleNotFoundError: No module named 'datasets'
Traceback (most recent call last):
  File "train.py", line 1, in <module>
    from datasets import load_from_disk, load_dataset
ModuleNotFoundError: No module named 'datasets'
Traceback (most recent call last):
  File "train.py", line 1, in <module>
    from datasets import load_from_disk, load_dataset
ModuleNotFoundError: No module named 'datasets'
Traceback (most recent call last):
  File "train.py", line 1, in <module>
    from datasets import load_from_disk, load_dataset
ModuleNotFoundError: No module named 'datasets'
Traceback (most recent call last):
  File "train.py", line 1, in <module>
    from datasets import load_from_disk, load_dataset
ModuleNotFoundError: No module named 'datasets'
[2024-03-07 10:54:12,499] torch.distributed.elastic.multiprocessing.api: [ERROR] failed (exitcode: 1) local_rank: 0 (pid: 405469) of binary: /opt/modules/i12g/anaconda/envs/jupyterhub/bin/python3.8
Traceback (most recent call last):
  File "/opt/modules/i12g/anaconda/envs/jupyterhub/bin/torchrun", line 8, in <module>
    sys.exit(main())
  File "/opt/modules/i12g/anaconda/envs/jupyterhub/lib/python3.8/site-packages/torch/distributed/elastic/multiprocessing/errors/__init__.py", line 346, in wrapper
    return f(*args, **kwargs)
  File "/opt/modules/i12g/anaconda/envs/jupyterhub/lib/python3.8/site-packages/torch/distributed/run.py", line 806, in main
    run(args)
  File "/opt/modules/i12g/anaconda/envs/jupyterhub/lib/python3.8/site-packages/torch/distributed/run.py", line 797, in run
    elastic_launch(
  File "/opt/modules/i12g/anaconda/envs/jupyterhub/lib/python3.8/site-packages/torch/distributed/launcher/api.py", line 134, in __call__
    return launch_agent(self._config, self._entrypoint, list(args))
  File "/opt/modules/i12g/anaconda/envs/jupyterhub/lib/python3.8/site-packages/torch/distributed/launcher/api.py", line 264, in launch_agent
    raise ChildFailedError(
torch.distributed.elastic.multiprocessing.errors.ChildFailedError: 
============================================================
train.py FAILED
------------------------------------------------------------
Failures:
  <NO_OTHER_FAILURES>
------------------------------------------------------------
Root Cause (first observed failure):
[0]:
  time      : 2024-03-07_10:54:12
  host      : ouga14.cmm.in.tum.de
  rank      : 0 (local_rank: 0)
  exitcode  : 1 (pid: 405469)
  error_file: <N/A>
  traceback : To enable traceback see: https://pytorch.org/docs/stable/elastic/errors.html
============================================================
[2024-03-07 10:54:12,592] torch.distributed.elastic.multiprocessing.api: [ERROR] failed (exitcode: 1) local_rank: 0 (pid: 405471) of binary: /opt/modules/i12g/anaconda/envs/jupyterhub/bin/python3.8
Traceback (most recent call last):
  File "/opt/modules/i12g/anaconda/envs/jupyterhub/bin/torchrun", line 8, in <module>
    sys.exit(main())
  File "/opt/modules/i12g/anaconda/envs/jupyterhub/lib/python3.8/site-packages/torch/distributed/elastic/multiprocessing/errors/__init__.py", line 346, in wrapper
    return f(*args, **kwargs)
  File "/opt/modules/i12g/anaconda/envs/jupyterhub/lib/python3.8/site-packages/torch/distributed/run.py", line 806, in main
    run(args)
  File "/opt/modules/i12g/anaconda/envs/jupyterhub/lib/python3.8/site-packages/torch/distributed/run.py", line 797, in run
    elastic_launch(
  File "/opt/modules/i12g/anaconda/envs/jupyterhub/lib/python3.8/site-packages/torch/distributed/launcher/api.py", line 134, in __call__
    return launch_agent(self._config, self._entrypoint, list(args))
  File "/opt/modules/i12g/anaconda/envs/jupyterhub/lib/python3.8/site-packages/torch/distributed/launcher/api.py", line 264, in launch_agent
    raise ChildFailedError(
torch.distributed.elastic.multiprocessing.errors.ChildFailedError: 
============================================================
train.py FAILED
------------------------------------------------------------
Failures:
  <NO_OTHER_FAILURES>
------------------------------------------------------------
Root Cause (first observed failure):
[0]:
  time      : 2024-03-07_10:54:12
  host      : ouga14.cmm.in.tum.de
  rank      : 0 (local_rank: 0)
  exitcode  : 1 (pid: 405471)
  error_file: <N/A>
  traceback : To enable traceback see: https://pytorch.org/docs/stable/elastic/errors.html
============================================================
[2024-03-07 10:54:12,603] torch.distributed.elastic.multiprocessing.api: [ERROR] failed (exitcode: 1) local_rank: 0 (pid: 405473) of binary: /opt/modules/i12g/anaconda/envs/jupyterhub/bin/python3.8
Traceback (most recent call last):
  File "/opt/modules/i12g/anaconda/envs/jupyterhub/bin/torchrun", line 8, in <module>
    sys.exit(main())
  File "/opt/modules/i12g/anaconda/envs/jupyterhub/lib/python3.8/site-packages/torch/distributed/elastic/multiprocessing/errors/__init__.py", line 346, in wrapper
    return f(*args, **kwargs)
  File "/opt/modules/i12g/anaconda/envs/jupyterhub/lib/python3.8/site-packages/torch/distributed/run.py", line 806, in main
    run(args)
  File "/opt/modules/i12g/anaconda/envs/jupyterhub/lib/python3.8/site-packages/torch/distributed/run.py", line 797, in run
    elastic_launch(
  File "/opt/modules/i12g/anaconda/envs/jupyterhub/lib/python3.8/site-packages/torch/distributed/launcher/api.py", line 134, in __call__
    return launch_agent(self._config, self._entrypoint, list(args))
  File "/opt/modules/i12g/anaconda/envs/jupyterhub/lib/python3.8/site-packages/torch/distributed/launcher/api.py", line 264, in launch_agent
    raise ChildFailedError(
torch.distributed.elastic.multiprocessing.errors.ChildFailedError: 
============================================================
train.py FAILED
------------------------------------------------------------
Failures:
  <NO_OTHER_FAILURES>
------------------------------------------------------------
Root Cause (first observed failure):
[0]:
  time      : 2024-03-07_10:54:12
  host      : ouga14.cmm.in.tum.de
  rank      : 0 (local_rank: 0)
  exitcode  : 1 (pid: 405473)
  error_file: <N/A>
  traceback : To enable traceback see: https://pytorch.org/docs/stable/elastic/errors.html
============================================================
[2024-03-07 10:54:12,678] torch.distributed.elastic.multiprocessing.api: [ERROR] failed (exitcode: 1) local_rank: 0 (pid: 405475) of binary: /opt/modules/i12g/anaconda/envs/jupyterhub/bin/python3.8
Traceback (most recent call last):
  File "/opt/modules/i12g/anaconda/envs/jupyterhub/bin/torchrun", line 8, in <module>
    sys.exit(main())
  File "/opt/modules/i12g/anaconda/envs/jupyterhub/lib/python3.8/site-packages/torch/distributed/elastic/multiprocessing/errors/__init__.py", line 346, in wrapper
    return f(*args, **kwargs)
  File "/opt/modules/i12g/anaconda/envs/jupyterhub/lib/python3.8/site-packages/torch/distributed/run.py", line 806, in main
    run(args)
  File "/opt/modules/i12g/anaconda/envs/jupyterhub/lib/python3.8/site-packages/torch/distributed/run.py", line 797, in run
    elastic_launch(
  File "/opt/modules/i12g/anaconda/envs/jupyterhub/lib/python3.8/site-packages/torch/distributed/launcher/api.py", line 134, in __call__
    return launch_agent(self._config, self._entrypoint, list(args))
  File "/opt/modules/i12g/anaconda/envs/jupyterhub/lib/python3.8/site-packages/torch/distributed/launcher/api.py", line 264, in launch_agent
    raise ChildFailedError(
torch.distributed.elastic.multiprocessing.errors.ChildFailedError: 
============================================================
train.py FAILED
------------------------------------------------------------
Failures:
  <NO_OTHER_FAILURES>
------------------------------------------------------------
Root Cause (first observed failure):
[0]:
  time      : 2024-03-07_10:54:12
  host      : ouga14.cmm.in.tum.de
  rank      : 0 (local_rank: 0)
  exitcode  : 1 (pid: 405475)
  error_file: <N/A>
  traceback : To enable traceback see: https://pytorch.org/docs/stable/elastic/errors.html
============================================================
[2024-03-07 10:54:12,705] torch.distributed.elastic.multiprocessing.api: [ERROR] failed (exitcode: 1) local_rank: 0 (pid: 405477) of binary: /opt/modules/i12g/anaconda/envs/jupyterhub/bin/python3.8
Traceback (most recent call last):
  File "/opt/modules/i12g/anaconda/envs/jupyterhub/bin/torchrun", line 8, in <module>
    sys.exit(main())
  File "/opt/modules/i12g/anaconda/envs/jupyterhub/lib/python3.8/site-packages/torch/distributed/elastic/multiprocessing/errors/__init__.py", line 346, in wrapper
    return f(*args, **kwargs)
  File "/opt/modules/i12g/anaconda/envs/jupyterhub/lib/python3.8/site-packages/torch/distributed/run.py", line 806, in main
    run(args)
  File "/opt/modules/i12g/anaconda/envs/jupyterhub/lib/python3.8/site-packages/torch/distributed/run.py", line 797, in run
    elastic_launch(
  File "/opt/modules/i12g/anaconda/envs/jupyterhub/lib/python3.8/site-packages/torch/distributed/launcher/api.py", line 134, in __call__
    return launch_agent(self._config, self._entrypoint, list(args))
  File "/opt/modules/i12g/anaconda/envs/jupyterhub/lib/python3.8/site-packages/torch/distributed/launcher/api.py", line 264, in launch_agent
    raise ChildFailedError(
torch.distributed.elastic.multiprocessing.errors.ChildFailedError: 
============================================================
train.py FAILED
------------------------------------------------------------
Failures:
  <NO_OTHER_FAILURES>
------------------------------------------------------------
Root Cause (first observed failure):
[0]:
  time      : 2024-03-07_10:54:12
  host      : ouga14.cmm.in.tum.de
  rank      : 0 (local_rank: 0)
  exitcode  : 1 (pid: 405477)
  error_file: <N/A>
  traceback : To enable traceback see: https://pytorch.org/docs/stable/elastic/errors.html
============================================================
[2024-03-07 10:54:12,770] torch.distributed.elastic.multiprocessing.api: [ERROR] failed (exitcode: 1) local_rank: 0 (pid: 405479) of binary: /opt/modules/i12g/anaconda/envs/jupyterhub/bin/python3.8
Traceback (most recent call last):
  File "/opt/modules/i12g/anaconda/envs/jupyterhub/bin/torchrun", line 8, in <module>
    sys.exit(main())
  File "/opt/modules/i12g/anaconda/envs/jupyterhub/lib/python3.8/site-packages/torch/distributed/elastic/multiprocessing/errors/__init__.py", line 346, in wrapper
    return f(*args, **kwargs)
  File "/opt/modules/i12g/anaconda/envs/jupyterhub/lib/python3.8/site-packages/torch/distributed/run.py", line 806, in main
    run(args)
  File "/opt/modules/i12g/anaconda/envs/jupyterhub/lib/python3.8/site-packages/torch/distributed/run.py", line 797, in run
    elastic_launch(
  File "/opt/modules/i12g/anaconda/envs/jupyterhub/lib/python3.8/site-packages/torch/distributed/launcher/api.py", line 134, in __call__
    return launch_agent(self._config, self._entrypoint, list(args))
  File "/opt/modules/i12g/anaconda/envs/jupyterhub/lib/python3.8/site-packages/torch/distributed/launcher/api.py", line 264, in launch_agent
    raise ChildFailedError(
torch.distributed.elastic.multiprocessing.errors.ChildFailedError: 
============================================================
train.py FAILED
------------------------------------------------------------
Failures:
  <NO_OTHER_FAILURES>
------------------------------------------------------------
Root Cause (first observed failure):
[0]:
  time      : 2024-03-07_10:54:12
  host      : ouga14.cmm.in.tum.de
  rank      : 0 (local_rank: 0)
  exitcode  : 1 (pid: 405479)
  error_file: <N/A>
  traceback : To enable traceback see: https://pytorch.org/docs/stable/elastic/errors.html
============================================================
srun: error: ouga14: tasks 0-5: Exited with exit code 1
